/*
Обработка ошибок

Что происходит в случае ошибок ?

const fnWithError = () => {
    throw new Error('Some error')           
}
fnWithError()                   выполнение кода остановится после появления Uncaught ошибки
console.log('Continue...')


*/